[INFO] [14:17:57] [MainThread] - СКРИПТ ЗАПУЩЕН!
[WARNING] [14:18:03] [Thread-1 (warp1)] - Зеленый не найден! Перепроверяю........
[WARNING] [14:18:16] [Thread-7 (warp1)] - Не могу найти фиолетовый! Пролистываю.....
[WARNING] [14:18:19] [Thread-7 (warp1)] - Зеленый не найден! Перепроверяю........
[INFO] [14:18:20] [Thread-7 (warp1)] - Перепроверка неуспешна! Выключаю таймер и выставляю статус dock = 1
[INFO] [14:18:21] [Thread-7 (warp1)] - Запускаем функцию варпа!
[INFO] [14:19:35] [Thread-7 (warp1)] - Запускаем функцию разгрузки карго!
[INFO] [14:20:16] [Thread-7 (warp1)] - Запускаем функцию андока!
[INFO] [14:21:40] [Thread-7 (warp1)] - Выставляем dock = 0
[INFO] [14:21:40] [Thread-7 (warp1)] - Запускаем поток заново!
[INFO] [14:21:40] [Thread-7 (warp1)] - Запускаем поток карго по таймеру!
[WARNING] [14:30:32] [Thread-8 (warp1)] - Не могу найти фиолетовый! Пролистываю.....
[WARNING] [14:30:34] [Thread-8 (warp1)] - Зеленый не найден! Перепроверяю........
[INFO] [14:30:36] [Thread-8 (warp1)] - Перепроверка неуспешна! Выключаю таймер и выставляю статус dock = 1
[ERROR] [14:30:41] [Thread-8 (warp1)] - An error has been caught in function 'run', process 'MainProcess' (12676), thread 'Thread-8 (warp1)' (9372):
Traceback (most recent call last):

  File "C:\Users\denis\AppData\Local\Programs\Python\Python311\Lib\site-packages\urllib3\connection.py", line 200, in _new_conn
    sock = connection.create_connection(
           │          └ <function create_connection at 0x0000027248F28FE0>
           └ <module 'urllib3.util.connection' from 'C:\\Users\\denis\\AppData\\Local\\Programs\\Python\\Python311\\Lib\\site-packages\\ur...
  File "C:\Users\denis\AppData\Local\Programs\Python\Python311\Lib\site-packages\urllib3\util\connection.py", line 60, in create_connection
    for res in socket.getaddrinfo(host, port, family, socket.SOCK_STREAM):
               │      │           │     │     │       │      └ <SocketKind.SOCK_STREAM: 1>
               │      │           │     │     │       └ <module 'socket' from 'C:\\Users\\denis\\AppData\\Local\\Programs\\Python\\Python311\\Lib\\socket.py'>
               │      │           │     │     └ <AddressFamily.AF_UNSPEC: 0>
               │      │           │     └ 443
               │      │           └ 'api.telegram.org'
               │      └ <function getaddrinfo at 0x000002722F9B2DE0>
               └ <module 'socket' from 'C:\\Users\\denis\\AppData\\Local\\Programs\\Python\\Python311\\Lib\\socket.py'>
  File "C:\Users\denis\AppData\Local\Programs\Python\Python311\Lib\socket.py", line 962, in getaddrinfo
    for res in _socket.getaddrinfo(host, port, family, type, proto, flags):
               │       │           │     │     │       │     │      └ 0
               │       │           │     │     │       │     └ 0
               │       │           │     │     │       └ <SocketKind.SOCK_STREAM: 1>
               │       │           │     │     └ <AddressFamily.AF_UNSPEC: 0>
               │       │           │     └ 443
               │       │           └ 'api.telegram.org'
               │       └ <built-in function getaddrinfo>
               └ <module '_socket' from 'C:\\Users\\denis\\AppData\\Local\\Programs\\Python\\Python311\\DLLs\\_socket.pyd'>

socket.gaierror: [Errno 11001] getaddrinfo failed


The above exception was the direct cause of the following exception:


Traceback (most recent call last):

  File "C:\Users\denis\AppData\Local\Programs\Python\Python311\Lib\site-packages\urllib3\connectionpool.py", line 790, in urlopen
    response = self._make_request(
               │    └ <function HTTPConnectionPool._make_request at 0x0000027248FEA3E0>
               └ <urllib3.connectionpool.HTTPSConnectionPool object at 0x0000027249262E10>
  File "C:\Users\denis\AppData\Local\Programs\Python\Python311\Lib\site-packages\urllib3\connectionpool.py", line 491, in _make_request
    raise new_e
          └ NameResolutionError("<urllib3.connection.HTTPSConnection object at 0x0000027249263E90>: Failed to resolve 'api.telegram.org' ...
  File "C:\Users\denis\AppData\Local\Programs\Python\Python311\Lib\site-packages\urllib3\connectionpool.py", line 467, in _make_request
    self._validate_conn(conn)
    │    │              └ <urllib3.connection.HTTPSConnection object at 0x0000027249263E90>
    │    └ <function HTTPSConnectionPool._validate_conn at 0x0000027248FEA980>
    └ <urllib3.connectionpool.HTTPSConnectionPool object at 0x0000027249262E10>
  File "C:\Users\denis\AppData\Local\Programs\Python\Python311\Lib\site-packages\urllib3\connectionpool.py", line 1092, in _validate_conn
    conn.connect()
    │    └ <function HTTPSConnection.connect at 0x0000027248FDE840>
    └ <urllib3.connection.HTTPSConnection object at 0x0000027249263E90>
  File "C:\Users\denis\AppData\Local\Programs\Python\Python311\Lib\site-packages\urllib3\connection.py", line 604, in connect
    self.sock = sock = self._new_conn()
    │    │             │    └ <function HTTPConnection._new_conn at 0x0000027248FDDF80>
    │    │             └ <urllib3.connection.HTTPSConnection object at 0x0000027249263E90>
    │    └ None
    └ <urllib3.connection.HTTPSConnection object at 0x0000027249263E90>
  File "C:\Users\denis\AppData\Local\Programs\Python\Python311\Lib\site-packages\urllib3\connection.py", line 207, in _new_conn
    raise NameResolutionError(self.host, self, e) from e
          │                   │    │     └ <urllib3.connection.HTTPSConnection object at 0x0000027249263E90>
          │                   │    └ <property object at 0x0000027248FC9CB0>
          │                   └ <urllib3.connection.HTTPSConnection object at 0x0000027249263E90>
          └ <class 'urllib3.exceptions.NameResolutionError'>

urllib3.exceptions.NameResolutionError: <urllib3.connection.HTTPSConnection object at 0x0000027249263E90>: Failed to resolve 'api.telegram.org' ([Errno 11001] getaddrinfo failed)


The above exception was the direct cause of the following exception:


Traceback (most recent call last):

  File "C:\Users\denis\AppData\Local\Programs\Python\Python311\Lib\site-packages\requests\adapters.py", line 486, in send
    resp = conn.urlopen(
           │    └ <function HTTPConnectionPool.urlopen at 0x0000027248FEA5C0>
           └ <urllib3.connectionpool.HTTPSConnectionPool object at 0x0000027249262E10>
  File "C:\Users\denis\AppData\Local\Programs\Python\Python311\Lib\site-packages\urllib3\connectionpool.py", line 844, in urlopen
    retries = retries.increment(
              │       └ <function Retry.increment at 0x0000027248F2AF20>
              └ Retry(total=0, connect=None, read=False, redirect=None, status=None)
  File "C:\Users\denis\AppData\Local\Programs\Python\Python311\Lib\site-packages\urllib3\util\retry.py", line 515, in increment
    raise MaxRetryError(_pool, url, reason) from reason  # type: ignore[arg-type]
          │             │      │    │            └ NameResolutionError("<urllib3.connection.HTTPSConnection object at 0x0000027249263E90>: Failed to resolve 'api.telegram.org' ...
          │             │      │    └ NameResolutionError("<urllib3.connection.HTTPSConnection object at 0x0000027249263E90>: Failed to resolve 'api.telegram.org' ...
          │             │      └ '/bot5632127059:AAEQiCBHXBYZkRbRmT7q_DeknNXTvgHiMww/sendMessage'
          │             └ <urllib3.connectionpool.HTTPSConnectionPool object at 0x0000027249262E10>
          └ <class 'urllib3.exceptions.MaxRetryError'>

urllib3.exceptions.MaxRetryError: HTTPSConnectionPool(host='api.telegram.org', port=443): Max retries exceeded with url: /bot5632127059:AAEQiCBHXBYZkRbRmT7q_DeknNXTvgHiMww/sendMessage (Caused by NameResolutionError("<urllib3.connection.HTTPSConnection object at 0x0000027249263E90>: Failed to resolve 'api.telegram.org' ([Errno 11001] getaddrinfo failed)"))


During handling of the above exception, another exception occurred:


Traceback (most recent call last):

  File "C:\Users\denis\AppData\Local\Programs\Python\Python311\Lib\threading.py", line 995, in _bootstrap
    self._bootstrap_inner()
    │    └ <function Thread._bootstrap_inner at 0x000002722F66B240>
    └ <Thread(Thread-8 (warp1), started 9372)>
  File "C:\Users\denis\AppData\Local\Programs\Python\Python311\Lib\threading.py", line 1038, in _bootstrap_inner
    self.run()
    │    └ <function Thread.run at 0x000002722F66AF20>
    └ <Thread(Thread-8 (warp1), started 9372)>
> File "C:\Users\denis\AppData\Local\Programs\Python\Python311\Lib\threading.py", line 975, in run
    self._target(*self._args, **self._kwargs)
    │    │        │    │        │    └ {}
    │    │        │    │        └ <Thread(Thread-8 (warp1), started 9372)>
    │    │        │    └ ()
    │    │        └ <Thread(Thread-8 (warp1), started 9372)>
    │    └ <function warp1 at 0x000002724924C040>
    └ <Thread(Thread-8 (warp1), started 9372)>

  File "d:\covetor\avto_telegram2.py", line 50, in warp1
    functions.teleg_message("Варп в док")
    │         └ <function teleg_message at 0x00000272318C0220>
    └ <module 'functions' from 'd:\\covetor\\functions.py'>

  File "d:\covetor\functions.py", line 14, in teleg_message
    r = requests.post(method, data={"chat_id": channel_id,"text": text})
        │        │    │                        │                  └ 'Варп в док'
        │        │    │                        └ '@wixiorbot'
        │        │    └ 'https://api.telegram.org/bot5632127059:AAEQiCBHXBYZkRbRmT7q_DeknNXTvgHiMww/sendMessage'
        │        └ <function post at 0x0000027249207BA0>
        └ <module 'requests' from 'C:\\Users\\denis\\AppData\\Local\\Programs\\Python\\Python311\\Lib\\site-packages\\requests\\__init_...

  File "C:\Users\denis\AppData\Local\Programs\Python\Python311\Lib\site-packages\requests\api.py", line 115, in post
    return request("post", url, data=data, json=json, **kwargs)
           │               │         │          │       └ {}
           │               │         │          └ None
           │               │         └ {'chat_id': '@wixiorbot', 'text': 'Варп в док'}
           │               └ 'https://api.telegram.org/bot5632127059:AAEQiCBHXBYZkRbRmT7q_DeknNXTvgHiMww/sendMessage'
           └ <function request at 0x00000272491DCFE0>
  File "C:\Users\denis\AppData\Local\Programs\Python\Python311\Lib\site-packages\requests\api.py", line 59, in request
    return session.request(method=method, url=url, **kwargs)
           │       │              │           │      └ {'data': {'chat_id': '@wixiorbot', 'text': 'Варп в док'}, 'json': None}
           │       │              │           └ 'https://api.telegram.org/bot5632127059:AAEQiCBHXBYZkRbRmT7q_DeknNXTvgHiMww/sendMessage'
           │       │              └ 'post'
           │       └ <function Session.request at 0x0000027249207060>
           └ <requests.sessions.Session object at 0x000002724924BF50>
  File "C:\Users\denis\AppData\Local\Programs\Python\Python311\Lib\site-packages\requests\sessions.py", line 589, in request
    resp = self.send(prep, **send_kwargs)
           │    │    │       └ {'timeout': None, 'allow_redirects': True, 'proxies': OrderedDict(), 'stream': False, 'verify': True, 'cert': None}
           │    │    └ <PreparedRequest [POST]>
           │    └ <function Session.send at 0x0000027249207560>
           └ <requests.sessions.Session object at 0x000002724924BF50>
  File "C:\Users\denis\AppData\Local\Programs\Python\Python311\Lib\site-packages\requests\sessions.py", line 703, in send
    r = adapter.send(request, **kwargs)
        │       │    │          └ {'timeout': None, 'proxies': OrderedDict(), 'stream': False, 'verify': True, 'cert': None}
        │       │    └ <PreparedRequest [POST]>
        │       └ <function HTTPAdapter.send at 0x00000272492068E0>
        └ <requests.adapters.HTTPAdapter object at 0x0000027249261990>
  File "C:\Users\denis\AppData\Local\Programs\Python\Python311\Lib\site-packages\requests\adapters.py", line 519, in send
    raise ConnectionError(e, request=request)
          │                          └ <PreparedRequest [POST]>
          └ <class 'requests.exceptions.ConnectionError'>

requests.exceptions.ConnectionError: HTTPSConnectionPool(host='api.telegram.org', port=443): Max retries exceeded with url: /bot5632127059:AAEQiCBHXBYZkRbRmT7q_DeknNXTvgHiMww/sendMessage (Caused by NameResolutionError("<urllib3.connection.HTTPSConnection object at 0x0000027249263E90>: Failed to resolve 'api.telegram.org' ([Errno 11001] getaddrinfo failed)"))
